Workbook
Name Slicer_Category: #N/A
Name Slicer_Gender: #N/A
Name Slicer_Order_Date__Year: #N/A
Name Slicer_Payment_Type: #N/A
Name Slicer_State: #N/A
Name Slicer_Store_ID: #N/A

Sheet Customer_Dim
A1: Customer_ID | B1: Name | C1: Age | D1: Gender | E1: City | F1: State | G1: Country | H1: Loyalty_Level
A2: CUST1000 | B2: sheena bonilla | C2: 55 | D2: Male | E2: Donaldton | F2: North Carolina | G2: USA
A3: CUST1001 | B3: Eugene Nelson | C3: 26 | D3: Female | E3: Phillipsmouth | F3: North Dakota | G3: USA | H3: Platinum
A4: CUST1002 | B4: dr. Benjamin Price | C4: 29 | D4: Female | E4: Kylebury | F4: Alabama | G4: USA | H4: Platinum
A5: CUST1003 | B5: jeremy harris | C5: 59 | D5: Female | E5: Thomastown | F5: Ohio | G5: USA | H5: Bronze
A6: CUST1004 | B6: Caroline Collins | C6: 64 | D6: Female | E6: Nicholasshire | F6: California | G6: USA | H6: Silver
A7: CUST1005 | B7: Christine Vaughn | C7: 24 | D7: Male | E7: East Amandamouth | F7: Oregon | G7: USA | H7: Bronze
A8: CUST1006 | B8: Amber Jackson | C8: 29 | D8: Female | E8: Deborahborough | F8: South Dakota | G8: USA | H8: Platinum
A9: CUST1007 | B9: Daniel Boyd | C9: 29 | D9: Female | E9: West Pamelafurt | F9: West Virginia | G9: USA | H9: Bronze
A10: CUST1008 | B10: Melissa Howard | C10: 53 | D10: Female | E10: Maynardton | F10: New Hampshire | G10: USA | H10: Gold
A11: CUST1009 | B11: Ms. Maria Leach | C11: 64 | D11: Male | E11: Melissashire | F11: Pennsylvania | G11: USA | H11: Platinum
A12: CUST1010 | B12: Dominic Page | C12: 53 | D12: Male | E12: Port Michaelburgh | F12: Pennsylvania | G12: USA | H12: Bronze
A13: CUST1011 | B13: Brian Lopez | C13: 28 | D13: Female | E13: East Krista | F13: New York | G13: USA | H13: Gold
A14: CUST1012 | B14: Kenneth Lambert | C14: 55 | D14: Female | E14: North Kathryn | F14: Kansas | G14: USA | H14: Platinum
... A19: CUST1017 | B19: Adam Cruz | C19: 60 | D19: Female | E19: Brandonville | F19: Georgia | G19: USA | H19: Platinum
A20: CUST1018 | B20: Rhonda Moss | C20: 43 | D20: Male | E20: South William | F20: Kansas | G20: USA
A21: CUST1019 | B21: Michael Torres | C21: 46 | D21: Female | E21: Gonzalezfort | F21: New Jersey | G21: USA | H21: Platinum
A22: CUST1020 | B22: Bridget Allen | C22: 59 | D22: Male | E22: Lake Shaneburgh | F22: Delaware | G22: USA | H22: Silver
A23: CUST1021 | B23: Jeff Martinez | C23: 36 | D23: Female | E23: Smithburgh | F23: Oklahoma | G23: USA | H23: Gold
A24: CUST1022 | B24: paul fox | C24: 33 | D24: Female | E24: Michaelton | F24: Hawaii | G24: USA | H24: Silver
A25: CUST1023 | B25: Jonathan Steele | C25: 52 | D25: Female | E25: Molinabury | F25: Oregon | G25: USA | H25: Silver
A26: CUST1024 | B26: Heather Collins | C26: 40 | D26: Male | E26: Rogerschester | F26: Idaho | G26: USA | H26: Platinum
A27: CUST1025 | B27: Diana Taylor | C27: 59 | D27: Female | E27: Vasqueztown | F27: California | G27: USA | H27: Bronze
A28: CUST1026 | B28: Amber Carlson | C28: 18 | D28: Female | E28: East Michellemouth | F28: Missouri | G28: USA | H28: Gold
A29: CUST1027 | B29: Leslie Johnson | C29: 31 | D29: Male | E29: Mollyshire | F29: Utah | G29: USA
A30: CUST1028 | B30: Joshua Ryan | C30: 27 | D30: Female | E30: New David | F30: New Jersey | G30: USA | H30: Platinum
A31: CUST1029 | B31: David Arnold | C31: 54 | D31: Female | E31: East Jennifer | F31: California | G31: USA | H31: Silver
A32: CUST1030 | B32: Jessica Acevedo | C32: 64 | D32: Female | E32: Amybury | F32: Pennsylvania | G32: USA | H32: Bronze
A33: CUST1031 | B33: Sarah Vance | C33: 41 | D33: Male | E33: Johnsonville | F33: Oregon | G33: USA | H33: Silver
A34: CUST1032 | B34: Mike Jennings | C34: 48 | D34: Female | E34: Fostermouth | F34: Arizona | G34: USA | H34: Gold
A35: CUST1033 | B35: Robert Jones DDS | C35: 25 | D35: Male | E35: Tristanton | F35: Oklahoma | G35: USA | H35: Platinum
A36: CUST1034 | B36: Christopher Olson | C36: 27 | D36: Female | E36: West Richard | F36: Maryland | G36: USA | H36: Platinum
A37: CUST1035 | B37: Rachel Myers | C37: 52 | D37: Male | E37: Robertberg | F37: North Dakota | G37: USA | H37: Silver
A38: CUST1036 | B38: Thomas Phillips | C38: 20 | D38: Female | E38: Luisfurt | F38: Georgia | G38: USA | H38: Gold
A39: CUST1037 | B39: Christopher Carter | C39: 27 | D39: Female | E39: Brendastad | F39: South Dakota | G39: USA
A40: CUST1038 | B40: Deanna Simpson | C40: 35 | D40: Female | E40: Brownport | F40: North Dakota | G40: USA | H40: Bronze
A41: CUST1039 | B41: Tonya Reynolds | C41: 55 | D41: Female | E41: Darleneton | F41: Michigan | G41: USA | H41: Gold
A42: CUST1040 | B42: Eric Vega | C42: 50 | D42: Male | E42: Williamsonland | F42: Kansas | G42: USA | H42: Gold
A43: CUST1041 | B43: James Gibbs | C43: 21 | D43: Male | E43: Mooneyshire | F43: Alaska | G43: USA | H43: Platinum
A44: CUST1042 | B44: William Martin | C44: 19 | D44: Male | E44: Ryanburgh | F44: Connecticut | G44: USA | H44: Platinum
...

Sheet Product_Dim
A1: Product_ID | B1: Product_Name | C1: Category | D1: Sub_Category | E1: Brand | F1: Cost | G1: Stock
A2: PROD0 | B2: Brother Laser Printer | C2: Electronics | D2: Computer | E2: Hunt Inc | F2: 112.42 | G2: 416
A3: PROD1 | B3: Men's Graphic T-Shirt | C3: Clothing | D3: Tops | E3: Terry-Moore | F3: 342.56 | G3: 181
A4: PROD2 | B4: Women's Casual Hoodie | C4: Clothing | D4: Outerwear | E4: Sims Inc | G4: 352
A5: P-3 | B5: Men's Running Jacket | C5: Clothing | D5: Outerwear | E5: Pineda Ltd | F5: 364.67 | G5: 452
A6: PROD4 | B6: Women's Yoga Pants | C6: Clothing | D6: Bottoms | E6: Gonzales-Davis | F6: 306.46 | G6: 487
A7: PROD5 | B7: Men's Leather Belt | C7: Clothing | D7: Accessories | E7: Baldwin, Garza and Gonzalez | F7: 261 | G7: 59
A8: PROD6 | B8: Herbal Face Moisturizer | C8: Beauty | D8: Skincare | E8: Davidson PLC | F8: 312.8 | G8: 350
A9: PROD7 | B9: LED Table Lamp | C9: Home | D9: Lighting | E9: Harrell LLC | F9: 218.86 | G9: 170
A10: PROD8 | B10: Wireless Bluetooth Earbuds | C10: Electronics | D10: Audio | E10: Perez-Johnston | F10: 439.07 | G10: 142
A11: PROD9 | B11: Adjustable Dumbbell Set | C11: Sports | D11: Fitness | E11: Hill PLC | F11: 495.72 | G11: 323
A12: PROD10 | B12: Ceramic Kitchen Bowl Set | C12: Home | D12: Kitchen | E12: Hamilton Group | F12: 298.86 | G12: 308
A13: PROD11 | B13: HD Smart TV Stick | C13: Electronics | D13: Accessories | E13: Gibson, Hobbs and Weaver | F13: 449.4
A14: PROD12 | B14: Hair Strengthening Shampoo | C14: Beauty | D14: Haircare | E14: Rice LLC | F14: 115.82 | G14: 460
A15: PROD13 | B15: USB-C Fast Charger | C15: Electronics | D15: Accessories | E15: Dawson-Perkins | F15: 242.23 | G15: 453
A16: PROD14 | B16: Decorative Wall Mirror | C16: Home | D16: Decor | E16: Luna, Anderson and Bowman | F16: 48.01 | G16: 439
A17: PROD15 | B17: 4K Home Projector | C17: Electronics | D17: Appliances | E17: Thomas LLC | F17: 465.34 | G17: 301
A18: P-16 | B18: Beard Grooming Kit | C18: Beauty | D18: Grooming | E18: Erickson-Green | F18: 337.42 | G18: 256
A19: PROD17 | B19: Soccer Training Cone Set | C19: Sports | D19: Accessories | E19: Ford, Murphy and Wilson | F19: 144.53 | G19: 367
A20: PROD18 | B20: Women's Denim Jeans | C20: Clothing | D20: Bottoms | E20: Guerra-Hendrix | G20: 343
A21: PROD19 | B21: Knee Support Brace | C21: Sports | D21: Equipment | E21: May-Reese | F21: 21.34 | G21: 65
A22: PROD20 | B22: Outdoor Sports Water Bottle | C22: Sports | D22: Accessories | E22: Soto-Ellis | F22: 131.51
A23: PROD21 | B23: Multi-Purpose Storage Box | C23: Home | D23: Storage | E23: Gardner-Montes | F23: 123.46 | G23: 76
A24: PROD22 | B24: Carbon Fiber Tennis Racket | C24: Sports | D24: Equipment | E24: Flores, Pineda and Rodriguez | F24: 484.62 | G24: 432
A25: PROD23 | B25: Men's Formal Shirt | C25: Clothing | D25: Tops | E25: Moon, Mora and Santos | G25: 360
A26: PROD24 | B26: Foldable Camping Chair | C26: Sports | D26: Outdoor | E26: Cook Ltd | F26: 166.06 | G26: 340
A27: PROD25 | B27: Women's Scarf Set | C27: Clothing | D27: Accessories | E27: Brown and Sons | F27: 174.02 | G27: 268
A28: PROD26 | B28: Wireless Bluetooth Speaker | C28: Electronics | D28: Audio | E28: Reed-Schmidt | F28: 322.41 | G28: 213
A29: PROD27 | B29: Decorative Floor Vase | C29: Home | D29: Decor | E29: Khan, Jones and Paul | G29: 378
A30: PROD28 | B30: Sports Stopwatch Timer | C30: Sports | D30: Accessories | E30: Burns-Hansen | F30: 38.76 | G30: 137
A31: PROD29 | B31: Fabric Sofa Throw Blanket | C31: Home | D31: Decor | E31: Hoffman Group | F31: 218.48 | G31: 276
A32: PROD30 | B32: Stainless Steel Cutlery Set | C32: Home | D32: Kitchen | E32: Stevens, Fernandez and Martin | F32: 19.52 | G32: 57
A33: PROD31 | B33: Basketball | C33: Sports | D33: Team Sports | E33: Nolan-Snow | F33: 204.39 | G33: 281
A34: PROD32 | B34: Vitamin C Face Serum | C34: Beauty | D34: Skincare | E34: Griffin Ltd | F34: 283.83 | G34: 244
A35: PROD33 | B35: Modern Wall Clock | C35: Home | D35: Decor | E35: Weiss-Watson | F35: 179.77 | G35: 305
A36: PROD34 | B36: Gaming Mechanical Keyboard | C36: Electronics | D36: Computer | E36: Lucero LLC | F36: 419.28 | G36: 86
A37: PROD35 | B37: Bedroom Table Lamp | C37: Home | D37: Lighting | E37: Jones LLC | F37: 382.22 | G37: 329
A38: PROD36 | B38: Women's Summer Dress | C38: Clothing | D38: Tops | E38: Smith-Mills | F38: 223.43 | G38: 154
A39: PROD37 | B39: Men's Casual Sneakers | C39: Clothing | D39: Footwear | E39: Hogan-Lee | F39: 353.47 | G39: 214
A40: PROD38 | B40: Sports Water Hydration Pack | C40: Sports | D40: Outdoor | E40: Sims-Smith | F40: 135.61 | G40: 394
...

Sheet Sales_Fact
A1: Sales_ID | B1: Order_Date | C1: Customer_ID | D1: Product_ID | E1: Store_ID | F1: Quantity | G1: Unit_Price | H1: Discount | I1: Payment_Type | J1: Total_Amount
A2: SALE0 | B2: 45480 | C2: CUST1409 | D2: PROD0 | E2: STORE3 | F2: 1 | G2: 218.04 | H2: 0.09 | I2: Credit Card | J2: 198.4164
A3: SALE1 | B3: 45285 | C3: CUST1467 | D3: PROD0 | E3: STORE17 | F3: 3 | G3: 104.47 | H3: 0.27 | I3: PayPal | J3: 228.7893
A4: SALE2 | B4: 45446 | C4: CUST1056 | D4: PROD0 | E4: STORE8 | F4: 4 | G4: 914.05 | H4: 0.25 | I4: Credit Card | J4: 2742.15
A5: SALE3 | B5: 45259 | C5: CUST1346 | D5: PROD0 | E5: STORE8 | F5: 1 | G5: 921.51 | H5: 0.16 | I5: COD | J5: 774.0684
A6: SALE4 | B6: 45297 | C6: CUST1493 | D6: PROD0 | E6: STORE5 | F6: 3 | G6: 745.3 | H6: 0.18 | I6: Credit Card | J6: 1833.438
A7: SALE5 | B7: 45499 | C7: CUST1116 | D7: PROD0 | E7: STORE7 | F7: 3 | G7: 147.01 | H7: 0.19 | I7: COD | J7: 357.2343
A8: SALE6 | B8: 45850 | C8: CUST1016 | D8: PROD0 | E8: STORE4 | F8: 2 | G8: 785.31 | H8: 0.15 | I8: PayPal | J8: 1335.027
A9: SALE7 | B9: 45248 | C9: CUST1152 | D9: PROD0 | E9: STORE8 | F9: 4 | G9: 342.39 | H9: 0.23 | I9: PayPal | J9: 1054.5612
A10: SALE8 | B10: 45781 | C10: CUST1187 | D10: PROD0 | E10: STORE5 | G10: 448.25 | H10: 0.07 | I10: PayPal | J10: 1250.6175
A11: SALE9 | B11: 45869 | C11: CUST1464 | D11: PROD0 | E11: STORE0 | F11: 2 | G11: 873.17 | H11: 0.23 | I11: PayPal | J11: 1344.6818
A12: SALE10 | B12: 45335 | C12: CUST1065 | D12: PROD0 | E12: STORE14 | F12: 1 | G12: 278.63 | H12: 0.07 | I12: Credit Card | J12: 259.1259
A13: SALE11 | B13: 45801 | C13: CUST1320 | D13: PROD0 | E13: STORE1 | F13: 4 | G13: 286.92 | H13: 0.17 | I13: Credit Card | J13: 952.5744
A14: SALE12 | B14: 45528 | C14: CUST1237 | D14: PROD0 | E14: STORE4 | F14: 4 | G14: 644.58 | H14: 0.01 | I14: Credit Card | J14: 2552.5368
A15: SALE13 | B15: 45875 | C15: CUST1443 | D15: PROD0 | E15: STORE16 | F15: 2 | G15: 316.9 | H15: 0.3 | I15: PayPal | J15: 443.66
A16: SALE14 | B16: 45829 | C16: CUST1348 | D16: PROD0 | E16: STORE15 | F16: 4 | G16: 403.47 | H16: 0.29 | I16: PayPal | J16: 1145.8548
A17: SALE15 | B17: 45636 | C17: CUST1435 | D17: PROD0 | E17: STORE9 | G17: 871.34 | H17: 0.04 | I17: COD | J17: 2509.4592
A18: SALE16 | B18: 45913 | C18: CUST1276 | D18: PROD1 | E18: STORE19 | F18: 2 | G18: 451.98 | H18: 0.25 | I18: Credit Card | J18: 677.97
A19: SALE17 | B19: 45637 | C19: CUST1079 | D19: PROD1 | E19: STORE4 | F19: 2 | G19: 502.69 | H19: 0.23 | I19: Credit Card | J19: 774.1426
A20: SALE18 | B20: 45517 | C20: CUST1094 | D20: PROD1 | E20: STORE4 | F20: 2 | G20: 559.23 | H20: 0.25 | I20: COD | J20: 838.845
A21: SALE19 | B21: 45369 | C21: CUST1239 | D21: PROD1 | E21: STORE13 | F21: 4 | H21: 0.04 | I21: COD | J21: 1782.4512
A22: SALE20 | B22: 45843 | C22: CUST1144 | D22: PROD1 | E22: STORE17 | F22: 3 | G22: 986.04 | H22: 0.27 | I22: COD | J22: 2159.4276
A23: SALE21 | B23: 45447 | C23: CUST1396 | D23: PROD1 | E23: STORE18 | F23: 1 | G23: 589.56 | H23: 0.22 | I23: Credit Card | J23: 459.8568
A24: SALE22 | B24: 45394 | C24: CUST1476 | D24: PROD1 | E24: STORE10 | F24: 3 | G24: 979.42 | H24: 0.03 | I24: PayPal | J24: 2850.1122
A25: SALE23 | B25: 45466 | C25: CUST1368 | D25: PROD1 | E25: STORE8 | F25: 1 | G25: 719.28 | H25: 0.08 | I25: Credit Card | J25: 661.7376
A26: SALE24 | B26: 45908 | C26: CUST1186 | D26: PROD1 | E26: STORE6 | F26: 3 | G26: 77.6 | H26: 0.07 | I26: Credit Card | J26: 216.504
A27: SALE25 | B27: 45552 | C27: CUST1381 | D27: PROD1 | E27: STORE3 | F27: 4 | G27: 852.71 | H27: 0.14 | I27: PayPal | J27: 2933.3224
A28: SALE26 | B28: 45294 | C28: CUST1213 | D28: PROD1 | E28: STORE8 | F28: 4 | G28: 156.16 | I28: Credit Card | J28: 599.6544
A29: SALE27 | B29: 45710 | C29: CUST1200 | D29: PROD1 | E29: STORE8 | F29: 3 | G29: 815.49 | H29: 0.17 | I29: Credit Card | J29: 2030.5701
A30: SALE28 | B30: 45923 | C30: CUST1148 | D30: PROD1 | E30: STORE2 | F30: 2 | G30: 74.21 | H30: 0.11 | I30: PayPal | J30: 132.0938
A31: SALE29 | B31: 45302 | C31: CUST1348 | D31: PROD1 | E31: STORE3 | G31: 451.67 | H31: 0.15 | I31: Credit Card | J31: 1535.678
A32: SALE30 | B32: 45217 | C32: CUST1028 | D32: PROD1 | E32: STORE19 | F32: 1 | G32: 429.38 | H32: 0.13 | I32: PayPal | J32: 373.5606
A33: SALE31 | B33: 45593 | C33: CUST1412 | D33: PROD10 | E33: STORE12 | F33: 2 | G33: 148.96 | H33: 0.03 | I33: COD | J33: 288.9824
A34: SALE32 | B34: 45597 | C34: CUST1398 | D34: PROD10 | E34: STORE8 | F34: 4 | G34: 313.83 | H34: 0.08 | I34: Credit Card | J34: 1154.8944
A35: SALE33 | B35: 45620 | C35: CUST1453 | D35: PROD10 | E35: STORE6 | F35: 2 | G35: 717.31 | H35: 0.15 | I35: Credit Card | J35: 1219.427
A36: SALE34 | B36: 45215 | C36: CUST1344 | D36: PROD10 | E36: STORE1 | G36: 873.22 | H36: 0.18 | I36: Credit Card | J36: 2148.1212
A37: SALE35 | B37: 45878 | C37: CUST1218 | D37: PROD10 | E37: STORE3 | F37: 4 | G37: 109.36 | H37: 0.19 | I37: COD | J37: 354.3264
A38: SALE36 | B38: 45635 | C38: CUST1086 | D38: PROD10 | E38: STORE7 | F38: 3 | G38: 559.52 | H38: 0.16 | I38: PayPal | J38: 1409.9904
A39: SALE37 | B39: 45329 | C39: CUST1492 | D39: PROD10 | E39: STORE17 | F39: 3 | G39: 121.76 | H39: 0.27 | I39: PayPal | J39: 266.6544
A40: SALE38 | B40: 45378 | C40: CUST1189 | D40: PROD10 | E40: STORE13 | F40: 4 | G40: 735.32 | H40: 0.06 | I40: COD | J40: 2764.8032
...

Sheet Product_Dim Cleaning
A1: Product_ID | B1: Product_Name | C1: Category | D1: Sub_Category | E1: Brand | F1: Cost | G1: Stock | H1: cost1 | I1: Stock1
A2: PROD0 | B2: Brother Laser Printer | C2: Electronics | D2: Computer | E2: Hunt Inc | F2: 112.42 | G2: 416 | H2: =IF(F2="",AVERAGEIFS($F$2:$F$101,$C$2:$C$101,C2,$D$2:$D$101,D2),F2) -> 112.42 | I2: {=IF(G2="",MEDIAN(IF(($C$2:$C$101=C2)*($D$2:$D$101=D2),$G$2:$G$101)),G2)} -> 416
A3: PROD1 | B3: Men's Graphic T-Shirt | C3: Clothing | D3: Tops | E3: Terry-Moore | F3: 342.56 | G3: 181 | H3: =IF(F3="",AVERAGEIFS($F$2:$F$101,$C$2:$C$101,C3,$D$2:$D$101,D3),F3) -> 342.56 | I3: {=IF(G3="",MEDIAN(IF(($C$2:$C$101=C3)*($D$2:$D$101=D3),$G$2:$G$101)),G3)} -> 181
A4: PROD2 | B4: Women's Casual Hoodie | C4: Clothing | D4: Outerwear | E4: Sims Inc | G4: 352 | H4: =IF(F4="",AVERAGEIFS($F$2:$F$101,$C$2:$C$101,C4,$D$2:$D$101,D4),F4) -> 296.82667 | I4: {=IF(G4="",MEDIAN(IF(($C$2:$C$101=C4)*($D$2:$D$101=D4),$G$2:$G$101)),G4)} -> 352
A5: PROD3 | B5: Men's Running Jacket | C5: Clothing | D5: Outerwear | E5: Pineda Ltd | F5: 364.67 | G5: 452 | H5: =IF(F5="",AVERAGEIFS($F$2:$F$101,$C$2:$C$101,C5,$D$2:$D$101,D5),F5) -> 364.67 | I5: {=IF(G5="",MEDIAN(IF(($C$2:$C$101=C5)*($D$2:$D$101=D5),$G$2:$G$101)),G5)} -> 452
A6: PROD4 | B6: Women's Yoga Pants | C6: Clothing | D6: Bottoms | E6: Gonzales-Davis | F6: 306.46 | G6: 487 | H6: =IF(F6="",AVERAGEIFS($F$2:$F$101,$C$2:$C$101,C6,$D$2:$D$101,D6),F6) -> 306.46 | I6: {=IF(G6="",MEDIAN(IF(($C$2:$C$101=C6)*($D$2:$D$101=D6),$G$2:$G$101)),G6)} -> 487
A7: PROD5 | B7: Men's Leather Belt | C7: Clothing | D7: Accessories | E7: Baldwin, Garza and Gonzalez | F7: 261 | G7: 59 | H7: =IF(F7="",AVERAGEIFS($F$2:$F$101,$C$2:$C$101,C7,$D$2:$D$101,D7),F7) -> 261 | I7: {=IF(G7="",MEDIAN(IF(($C$2:$C$101=C7)*($D$2:$D$101=D7),$G$2:$G$101)),G7)} -> 59
A8: PROD6 | B8: Herbal Face Moisturizer | C8: Beauty | D8: Skincare | E8: Davidson PLC | F8: 312.8 | G8: 350 | H8: =IF(F8="",AVERAGEIFS($F$2:$F$101,$C$2:$C$101,C8,$D$2:$D$101,D8),F8) -> 312.8 | I8: {=IF(G8="",MEDIAN(IF(($C$2:$C$101=C8)*($D$2:$D$101=D8),$G$2:$G$101)),G8)} -> 350
A9: PROD7 | B9: LED Table Lamp | C9: Home | D9: Lighting | E9: Harrell LLC | F9: 218.86 | G9: 170 | H9: =IF(F9="",AVERAGEIFS($F$2:$F$101,$C$2:$C$101,C9,$D$2:$D$101,D9),F9) -> 218.86 | I9: {=IF(G9="",MEDIAN(IF(($C$2:$C$101=C9)*($D$2:$D$101=D9),$G$2:$G$101)),G9)} -> 170
A10: PROD8 | B10: Wireless Bluetooth Earbuds | C10: Electronics | D10: Audio | E10: Perez-Johnston | F10: 439.07 | G10: 142 | H10: =IF(F10="",AVERAGEIFS($F$2:$F$101,$C$2:$C$101,C10,$D$2:$D$101,D10),F10) -> 439.07 | I10: {=IF(G10="",MEDIAN(IF(($C$2:$C$101=C10)*($D$2:$D$101=D10),$G$2:$G$101)),G10)} -> 142
A11: PROD9 | B11: Adjustable Dumbbell Set | C11: Sports | D11: Fitness | E11: Hill PLC | F11: 495.72 | G11: 323 | H11: =IF(F11="",AVERAGEIFS($F$2:$F$101,$C$2:$C$101,C11,$D$2:$D$101,D11),F11) -> 495.72 | I11: {=IF(G11="",MEDIAN(IF(($C$2:$C$101=C11)*($D$2:$D$101=D11),$G$2:$G$101)),G11)} -> 323
A12: PROD10 | B12: Ceramic Kitchen Bowl Set | C12: Home | D12: Kitchen | E12: Hamilton Group | F12: 298.86 | G12: 308 | H12: =IF(F12="",AVERAGEIFS($F$2:$F$101,$C$2:$C$101,C12,$D$2:$D$101,D12),F12) -> 298.86 | I12: {=IF(G12="",MEDIAN(IF(($C$2:$C$101=C12)*($D$2:$D$101=D12),$G$2:$G$101)),G12)} -> 308
A13: PROD11 | B13: HD Smart TV Stick | C13: Electronics | D13: Accessories | E13: Gibson, Hobbs and Weaver | F13: 449.4 | H13: =IF(F13="",AVERAGEIFS($F$2:$F$101,$C$2:$C$101,C13,$D$2:$D$101,D13),F13) -> 449.4 | I13: {=IF(G13="",MEDIAN(IF(($C$2:$C$101=C13)*($D$2:$D$101=D13),$G$2:$G$101)),G13)} -> 361
A14: PROD12 | B14: Hair Strengthening Shampoo | C14: Beauty | D14: Haircare | E14: Rice LLC | F14: 115.82 | G14: 460 | H14: =IF(F14="",AVERAGEIFS($F$2:$F$101,$C$2:$C$101,C14,$D$2:$D$101,D14),F14) -> 115.82 | I14: {=IF(G14="",MEDIAN(IF(($C$2:$C$101=C14)*($D$2:$D$101=D14),$G$2:$G$101)),G14)} -> 460
A15: PROD13 | B15: USB-C Fast Charger | C15: Electronics | D15: Accessories | E15: Dawson-Perkins | F15: 242.23 | G15: 453 | H15: =IF(F15="",AVERAGEIFS($F$2:$F$101,$C$2:$C$101,C15,$D$2:$D$101,D15),F15) -> 242.23 | I15: {=IF(G15="",MEDIAN(IF(($C$2:$C$101=C15)*($D$2:$D$101=D15),$G$2:$G$101)),G15)} -> 453
A16: PROD14 | B16: Decorative Wall Mirror | C16: Home | D16: Decor | E16: Luna, Anderson and Bowman | F16: 48.01 | G16: 439 | H16: =IF(F16="",AVERAGEIFS($F$2:$F$101,$C$2:$C$101,C16,$D$2:$D$101,D16),F16) -> 48.01 | I16: {=IF(G16="",MEDIAN(IF(($C$2:$C$101=C16)*($D$2:$D$101=D16),$G$2:$G$101)),G16)} -> 439
A17: PROD15 | B17: 4K Home Projector | C17: Electronics | D17: Appliances | E17: Thomas LLC | F17: 465.34 | G17: 301 | H17: =IF(F17="",AVERAGEIFS($F$2:$F$101,$C$2:$C$101,C17,$D$2:$D$101,D17),F17) -> 465.34 | I17: {=IF(G17="",MEDIAN(IF(($C$2:$C$101=C17)*($D$2:$D$101=D17),$G$2:$G$101)),G17)} -> 301
A18: PROD16 | B18: Beard Grooming Kit | C18: Beauty | D18: Grooming | E18: Erickson-Green | F18: 337.42 | G18: 256 | H18: =IF(F18="",AVERAGEIFS($F$2:$F$101,$C$2:$C$101,C18,$D$2:$D$101,D18),F18) -> 337.42 | I18: {=IF(G18="",MEDIAN(IF(($C$2:$C$101=C18)*($D$2:$D$101=D18),$G$2:$G$101)),G18)} -> 256
A19: PROD17 | B19: Soccer Training Cone Set | C19: Sports | D19: Accessories | E19: Ford, Murphy and Wilson | F19: 144.53 | G19: 367 | H19: =IF(F19="",AVERAGEIFS($F$2:$F$101,$C$2:$C$101,C19,$D$2:$D$101,D19),F19) -> 144.53 | I19: {=IF(G19="",MEDIAN(IF(($C$2:$C$101=C19)*($D$2:$D$101=D19),$G$2:$G$101)),G19)} -> 367
A20: PROD18 | B20: Women's Denim Jeans | C20: Clothing | D20: Bottoms | E20: Guerra-Hendrix | G20: 343 | H20: =IF(F20="",AVERAGEIFS($F$2:$F$101,$C$2:$C$101,C20,$D$2:$D$101,D20),F20) -> 303.74667 | I20: {=IF(G20="",MEDIAN(IF(($C$2:$C$101=C20)*($D$2:$D$101=D20),$G$2:$G$101)),G20)} -> 343
A21: PROD19 | B21: Knee Support Brace | C21: Sports | D21: Equipment | E21: May-Reese | F21: 21.34 | G21: 65 | H21: =IF(F21="",AVERAGEIFS($F$2:$F$101,$C$2:$C$101,C21,$D$2:$D$101,D21),F21) -> 21.34 | I21: {=IF(G21="",MEDIAN(IF(($C$2:$C$101=C21)*($D$2:$D$101=D21),$G$2:$G$101)),G21)} -> 65
A22: PROD20 | B22: Outdoor Sports Water Bottle | C22: Sports | D22: Accessories | E22: Soto-Ellis | F22: 131.51 | H22: =IF(F22="",AVERAGEIFS($F$2:$F$101,$C$2:$C$101,C22,$D$2:$D$101,D22),F22) -> 131.51 | I22: {=IF(G22="",MEDIAN(IF(($C$2:$C$101=C22)*($D$2:$D$101=D22),$G$2:$G$101)),G22)} -> 161
A23: PROD21 | B23: Multi-Purpose Storage Box | C23: Home | D23: Storage | E23: Gardner-Montes | F23: 123.46 | G23: 76 | H23: =IF(F23="",AVERAGEIFS($F$2:$F$101,$C$2:$C$101,C23,$D$2:$D$101,D23),F23) -> 123.46 | I23: {=IF(G23="",MEDIAN(IF(($C$2:$C$101=C23)*($D$2:$D$101=D23),$G$2:$G$101)),G23)} -> 76
A24: PROD22 | B24: Carbon Fiber Tennis Racket | C24: Sports | D24: Equipment | E24: Flores, Pineda and Rodriguez | F24: 484.62 | G24: 432 | H24: =IF(F24="",AVERAGEIFS($F$2:$F$101,$C$2:$C$101,C24,$D$2:$D$101,D24),F24) -> 484.62 | I24: {=IF(G24="",MEDIAN(IF(($C$2:$C$101=C24)*($D$2:$D$101=D24),$G$2:$G$101)),G24)} -> 432
A25: PROD23 | B25: Men's Formal Shirt | C25: Clothing | D25: Tops | E25: Moon, Mora and Santos | G25: 360 | H25: =IF(F25="",AVERAGEIFS($F$2:$F$101,$C$2:$C$101,C25,$D$2:$D$101,D25),F25) -> 282.995 | I25: {=IF(G25="",MEDIAN(IF(($C$2:$C$101=C25)*($D$2:$D$101=D25),$G$2:$G$101)),G25)} -> 360
A26: PROD24 | B26: Foldable Camping Chair | C26: Sports | D26: Outdoor | E26: Cook Ltd | F26: 166.06 | G26: 340 | H26: =IF(F26="",AVERAGEIFS($F$2:$F$101,$C$2:$C$101,C26,$D$2:$D$101,D26),F26) -> 166.06 | I26: {=IF(G26="",MEDIAN(IF(($C$2:$C$101=C26)*($D$2:$D$101=D26),$G$2:$G$101)),G26)} -> 340
A27: PROD25 | B27: Women's Scarf Set | C27: Clothing | D27: Accessories | E27: Brown and Sons | F27: 174.02 | G27: 268 | H27: =IF(F27="",AVERAGEIFS($F$2:$F$101,$C$2:$C$101,C27,$D$2:$D$101,D27),F27) -> 174.02 | I27: {=IF(G27="",MEDIAN(IF(($C$2:$C$101=C27)*($D$2:$D$101=D27),$G$2:$G$101)),G27)} -> 268
A28: PROD26 | B28: Wireless Bluetooth Speaker | C28: Electronics | D28: Audio | E28: Reed-Schmidt | F28: 322.41 | G28: 213 | H28: =IF(F28="",AVERAGEIFS($F$2:$F$101,$C$2:$C$101,C28,$D$2:$D$101,D28),F28) -> 322.41 | I28: {=IF(G28="",MEDIAN(IF(($C$2:$C$101=C28)*($D$2:$D$101=D28),$G$2:$G$101)),G28)} -> 213
A29: PROD27 | B29: Decorative Floor Vase | C29: Home | D29: Decor | E29: Khan, Jones and Paul | G29: 378 | H29: =IF(F29="",AVERAGEIFS($F$2:$F$101,$C$2:$C$101,C29,$D$2:$D$101,D29),F29) -> 219.12333 | I29: {=IF(G29="",MEDIAN(IF(($C$2:$C$101=C29)*($D$2:$D$101=D29),$G$2:$G$101)),G29)} -> 378
A30: PROD28 | B30: Sports Stopwatch Timer | C30: Sports | D30: Accessories | E30: Burns-Hansen | F30: 38.76 | G30: 137 | H30: =IF(F30="",AVERAGEIFS($F$2:$F$101,$C$2:$C$101,C30,$D$2:$D$101,D30),F30) -> 38.76 | I30: {=IF(G30="",MEDIAN(IF(($C$2:$C$101=C30)*($D$2:$D$101=D30),$G$2:$G$101)),G30)} -> 137
A31: PROD29 | B31: Fabric Sofa Throw Blanket | C31: Home | D31: Decor | E31: Hoffman Group | F31: 218.48 | G31: 276 | H31: =IF(F31="",AVERAGEIFS($F$2:$F$101,$C$2:$C$101,C31,$D$2:$D$101,D31),F31) -> 218.48 | I31: {=IF(G31="",MEDIAN(IF(($C$2:$C$101=C31)*($D$2:$D$101=D31),$G$2:$G$101)),G31)} -> 276
A32: PROD30 | B32: Stainless Steel Cutlery Set | C32: Home | D32: Kitchen | E32: Stevens, Fernandez and Martin | F32: 19.52 | G32: 57 | H32: =IF(F32="",AVERAGEIFS($F$2:$F$101,$C$2:$C$101,C32,$D$2:$D$101,D32),F32) -> 19.52 | I32: {=IF(G32="",MEDIAN(IF(($C$2:$C$101=C32)*($D$2:$D$101=D32),$G$2:$G$101)),G32)} -> 57
A33: PROD31 | B33: Basketball | C33: Sports | D33: Team Sports | E33: Nolan-Snow | F33: 204.39 | G33: 281 | H33: =IF(F33="",AVERAGEIFS($F$2:$F$101,$C$2:$C$101,C33,$D$2:$D$101,D33),F33) -> 204.39 | I33: {=IF(G33="",MEDIAN(IF(($C$2:$C$101=C33)*($D$2:$D$101=D33),$G$2:$G$101)),G33)} -> 281
A34: PROD32 | B34: Vitamin C Face Serum | C34: Beauty | D34: Skincare | E34: Griffin Ltd | F34: 283.83 | G34: 244 | H34: =IF(F34="",AVERAGEIFS($F$2:$F$101,$C$2:$C$101,C34,$D$2:$D$101,D34),F34) -> 283.83 | I34: {=IF(G34="",MEDIAN(IF(($C$2:$C$101=C34)*($D$2:$D$101=D34),$G$2:$G$101)),G34)} -> 244
A35: PROD33 | B35: Modern Wall Clock | C35: Home | D35: Decor | E35: Weiss-Watson | F35: 179.77 | G35: 305 | H35: =IF(F35="",AVERAGEIFS($F$2:$F$101,$C$2:$C$101,C35,$D$2:$D$101,D35),F35) -> 179.77 | I35: {=IF(G35="",MEDIAN(IF(($C$2:$C$101=C35)*($D$2:$D$101=D35),$G$2:$G$101)),G35)} -> 305
A36: PROD34 | B36: Gaming Mechanical Keyboard | C36: Electronics | D36: Computer | E36: Lucero LLC | F36: 419.28 | G36: 86 | H36: =IF(F36="",AVERAGEIFS($F$2:$F$101,$C$2:$C$101,C36,$D$2:$D$101,D36),F36) -> 419.28 | I36: {=IF(G36="",MEDIAN(IF(($C$2:$C$101=C36)*($D$2:$D$101=D36),$G$2:$G$101)),G36)} -> 86
A37: PROD35 | B37: Bedroom Table Lamp | C37: Home | D37: Lighting | E37: Jones LLC | F37: 382.22 | G37: 329 | H37: =IF(F37="",AVERAGEIFS($F$2:$F$101,$C$2:$C$101,C37,$D$2:$D$101,D37),F37) -> 382.22 | I37: {=IF(G37="",MEDIAN(IF(($C$2:$C$101=C37)*($D$2:$D$101=D37),$G$2:$G$101)),G37)} -> 329
A38: PROD36 | B38: Women's Summer Dress | C38: Clothing | D38: Tops | E38: Smith-Mills | F38: 223.43 | G38: 154 | H38: =IF(F38="",AVERAGEIFS($F$2:$F$101,$C$2:$C$101,C38,$D$2:$D$101,D38),F38) -> 223.43 | I38: {=IF(G38="",MEDIAN(IF(($C$2:$C$101=C38)*($D$2:$D$101=D38),$G$2:$G$101)),G38)} -> 154
A39: PROD37 | B39: Men's Casual Sneakers | C39: Clothing | D39: Footwear | E39: Hogan-Lee | F39: 353.47 | G39: 214 | H39: =IF(F39="",AVERAGEIFS($F$2:$F$101,$C$2:$C$101,C39,$D$2:$D$101,D39),F39) -> 353.47 | I39: {=IF(G39="",MEDIAN(IF(($C$2:$C$101=C39)*($D$2:$D$101=D39),$G$2:$G$101)),G39)} -> 214
A40: PROD38 | B40: Sports Water Hydration Pack | C40: Sports | D40: Outdoor | E40: Sims-Smith | F40: 135.61 | G40: 394 | H40: =IF(F40="",AVERAGEIFS($F$2:$F$101,$C$2:$C$101,C40,$D$2:$D$101,D40),F40) -> 135.61 | I40: {=IF(G40="",MEDIAN(IF(($C$2:$C$101=C40)*($D$2:$D$101=D40),$G$2:$G$101)),G40)} -> 394
...

Sheet Sales_Fact Cleaning
A1: Sales_ID | B1: Order_Date | C1: Customer_ID | D1: Product_ID | E1: Store_ID | F1: Quantity | G1: Unit_Price | H1: Discount | I1: Payment_Type | J1: Total_Amount | K1: Quantity2 | L1: Unit_Price2 | M1: Discount3 | N1: Total_Amount2
A2: SALE0 | B2: 45480 | C2: CUST1409 | D2: PROD0 | E2: STORE3 | F2: 1 | G2: 218.04 | H2: 0.09 | I2: Credit Card | J2: 198.4164 | K2: =IF(F2="",N2/(G2*(1-H2)),F2) -> 1 | L2: =IF(G2="",Table8[[#This Row],[Total_Amount2]]/(Table8[[#This Row],[Quantity]]*(1-Table8[[#This Row],[Discount]])),G2) -> 218.04 | M2: =IF(H2="",1-(Table8[[#This Row],[Total_Amount2]]/(Table8[[#This Row],[Quantity]]*Table8[[#This Row],[Unit_Price]])),H2) -> 0.09 | N2: =IF(J2="",F2*G2*(1-H2),J2) -> 198.4164
A3: SALE1 | B3: 45285 | C3: CUST1467 | D3: PROD0 | E3: STORE17 | F3: 3 | G3: 104.47 | H3: 0.27 | I3: PayPal | J3: 228.7893 | K3: =IF(F3="",N3/(G3*(1-H3)),F3) -> 3 | L3: =IF(G3="",Table8[[#This Row],[Total_Amount2]]/(Table8[[#This Row],[Quantity]]*(1-Table8[[#This Row],[Discount]])),G3) -> 104.47 | M3: =IF(H3="",1-(Table8[[#This Row],[Total_Amount2]]/(Table8[[#This Row],[Quantity]]*Table8[[#This Row],[Unit_Price]])),H3) -> 0.27 | N3: =IF(J3="",F3*G3*(1-H3),J3) -> 228.7893
A4: SALE2 | B4: 45446 | C4: CUST1056 | D4: PROD0 | E4: STORE8 | F4: 4 | G4: 914.05 | H4: 0.25 | I4: Credit Card | J4: 2742.15 | K4: =IF(F4="",N4/(G4*(1-H4)),F4) -> 4 | L4: =IF(G4="",Table8[[#This Row],[Total_Amount2]]/(Table8[[#This Row],[Quantity]]*(1-Table8[[#This Row],[Discount]])),G4) -> 914.05 | M4: =IF(H4="",1-(Table8[[#This Row],[Total_Amount2]]/(Table8[[#This Row],[Quantity]]*Table8[[#This Row],[Unit_Price]])),H4) -> 0.25 | N4: =IF(J4="",F4*G4*(1-H4),J4) -> 2742.15
A5: SALE3 | B5: 45259 | C5: CUST1346 | D5: PROD0 | E5: STORE8 | F5: 1 | G5: 921.51 | H5: 0.16 | I5: COD | J5: 774.0684 | K5: =IF(F5="",N5/(G5*(1-H5)),F5) -> 1 | L5: =IF(G5="",Table8[[#This Row],[Total_Amount2]]/(Table8[[#This Row],[Quantity]]*(1-Table8[[#This Row],[Discount]])),G5) -> 921.51 | M5: =IF(H5="",1-(Table8[[#This Row],[Total_Amount2]]/(Table8[[#This Row],[Quantity]]*Table8[[#This Row],[Unit_Price]])),H5) -> 0.16 | N5: =IF(J5="",F5*G5*(1-H5),J5) -> 774.0684
A6: SALE4 | B6: 45297 | C6: CUST1493 | D6: PROD0 | E6: STORE5 | F6: 3 | G6: 745.3 | H6: 0.18 | I6: Credit Card | J6: 1833.438 | K6: =IF(F6="",N6/(G6*(1-H6)),F6) -> 3 | L6: =IF(G6="",Table8[[#This Row],[Total_Amount2]]/(Table8[[#This Row],[Quantity]]*(1-Table8[[#This Row],[Discount]])),G6) -> 745.3 | M6: =IF(H6="",1-(Table8[[#This Row],[Total_Amount2]]/(Table8[[#This Row],[Quantity]]*Table8[[#This Row],[Unit_Price]])),H6) -> 0.18 | N6: =IF(J6="",F6*G6*(1-H6),J6) -> 1833.438
A7: SALE5 | B7: 45499 | C7: CUST1116 | D7: PROD0 | E7: STORE7 | F7: 3 | G7: 147.01 | H7: 0.19 | I7: COD | J7: 357.2343 | K7: =IF(F7="",N7/(G7*(1-H7)),F7) -> 3 | L7: =IF(G7="",Table8[[#This Row],[Total_Amount2]]/(Table8[[#This Row],[Quantity]]*(1-Table8[[#This Row],[Discount]])),G7) -> 147.01 | M7: =IF(H7="",1-(Table8[[#This Row],[Total_Amount2]]/(Table8[[#This Row],[Quantity]]*Table8[[#This Row],[Unit_Price]])),H7) -> 0.19 | N7: =IF(J7="",F7*G7*(1-H7),J7) -> 357.2343
A8: SALE6 | B8: 45850 | C8: CUST1016 | D8: PROD0 | E8: STORE4 | F8: 2 | G8: 785.31 | H8: 0.15 | I8: PayPal | J8: 1335.027 | K8: =IF(F8="",N8/(G8*(1-H8)),F8) -> 2 | L8: =IF(G8="",Table8[[#This Row],[Total_Amount2]]/(Table8[[#This Row],[Quantity]]*(1-Table8[[#This Row],[Discount]])),G8) -> 785.31 | M8: =IF(H8="",1-(Table8[[#This Row],[Total_Amount2]]/(Table8[[#This Row],[Quantity]]*Table8[[#This Row],[Unit_Price]])),H8) -> 0.15 | N8: =IF(J8="",F8*G8*(1-H8),J8) -> 1335.027
A9: SALE7 | B9: 45248 | C9: CUST1152 | D9: PROD0 | E9: STORE8 | F9: 4 | G9: 342.39 | H9: 0.23 | I9: PayPal | J9: 1054.5612 | K9: =IF(F9="",N9/(G9*(1-H9)),F9) -> 4 | L9: =IF(G9="",Table8[[#This Row],[Total_Amount2]]/(Table8[[#This Row],[Quantity]]*(1-Table8[[#This Row],[Discount]])),G9) -> 342.39 | M9: =IF(H9="",1-(Table8[[#This Row],[Total_Amount2]]/(Table8[[#This Row],[Quantity]]*Table8[[#This Row],[Unit_Price]])),H9) -> 0.23 | N9: =IF(J9="",F9*G9*(1-H9),J9) -> 1054.5612
A10: SALE8 | B10: 45781 | C10: CUST1187 | D10: PROD0 | E10: STORE5 | G10: 448.25 | H10: 0.07 | I10: PayPal | J10: 1250.6175 | K10: =IF(F10="",N10/(G10*(1-H10)),F10) -> 3 | L10: =IF(G10="",Table8[[#This Row],[Total_Amount2]]/(Table8[[#This Row],[Quantity]]*(1-Table8[[#This Row],[Discount]])),G10) -> 448.25 | M10: =IF(H10="",1-(Table8[[#This Row],[Total_Amount2]]/(Table8[[#This Row],[Quantity]]*Table8[[#This Row],[Unit_Price]])),H10) -> 0.07 | N10: =IF(J10="",F10*G10*(1-H10),J10) -> 1250.6175
A11: SALE9 | B11: 45869 | C11: CUST1464 | D11: PROD0 | E11: STORE0 | F11: 2 | G11: 873.17 | H11: 0.23 | I11: PayPal | J11: 1344.6818 | K11: =IF(F11="",N11/(G11*(1-H11)),F11) -> 2 | L11: =IF(G11="",Table8[[#This Row],[Total_Amount2]]/(Table8[[#This Row],[Quantity]]*(1-Table8[[#This Row],[Discount]])),G11) -> 873.17 | M11: =IF(H11="",1-(Table8[[#This Row],[Total_Amount2]]/(Table8[[#This Row],[Quantity]]*Table8[[#This Row],[Unit_Price]])),H11) -> 0.23 | N11: =IF(J11="",F11*G11*(1-H11),J11) -> 1344.6818
A12: SALE10 | B12: 45335 | C12: CUST1065 | D12: PROD0 | E12: STORE14 | F12: 1 | G12: 278.63 | H12: 0.07 | I12: Credit Card | J12: 259.1259 | K12: =IF(F12="",N12/(G12*(1-H12)),F12) -> 1 | L12: =IF(G12="",Table8[[#This Row],[Total_Amount2]]/(Table8[[#This Row],[Quantity]]*(1-Table8[[#This Row],[Discount]])),G12) -> 278.63 | M12: =IF(H12="",1-(Table8[[#This Row],[Total_Amount2]]/(Table8[[#This Row],[Quantity]]*Table8[[#This Row],[Unit_Price]])),H12) -> 0.07 | N12: =IF(J12="",F12*G12*(1-H12),J12) -> 259.1259
A13: SALE11 | B13: 45801 | C13: CUST1320 | D13: PROD0 | E13: STORE1 | F13: 4 | G13: 286.92 | H13: 0.17 | I13: Credit Card | J13: 952.5744 | K13: =IF(F13="",N13/(G13*(1-H13)),F13) -> 4 | L13: =IF(G13="",Table8[[#This Row],[Total_Amount2]]/(Table8[[#This Row],[Quantity]]*(1-Table8[[#This Row],[Discount]])),G13) -> 286.92 | M13: =IF(H13="",1-(Table8[[#This Row],[Total_Amount2]]/(Table8[[#This Row],[Quantity]]*Table8[[#This Row],[Unit_Price]])),H13) -> 0.17 | N13: =IF(J13="",F13*G13*(1-H13),J13) -> 952.5744
A14: SALE12 | B14: 45528 | C14: CUST1237 | D14: PROD0 | E14: STORE4 | F14: 4 | G14: 644.58 | H14: 0.01 | I14: Credit Card | J14: 2552.5368 | K14: =IF(F14="",N14/(G14*(1-H14)),F14) -> 4 | L14: =IF(G14="",Table8[[#This Row],[Total_Amount2]]/(Table8[[#This Row],[Quantity]]*(1-Table8[[#This Row],[Discount]])),G14) -> 644.58 | M14: =IF(H14="",1-(Table8[[#This Row],[Total_Amount2]]/(Table8[[#This Row],[Quantity]]*Table8[[#This Row],[Unit_Price]])),H14) -> 0.01 | N14: =IF(J14="",F14*G14*(1-H14),J14) -> 2552.5368
A15: SALE13 | B15: 45875 | C15: CUST1443 | D15: PROD0 | E15: STORE16 | F15: 2 | G15: 316.9 | H15: 0.3 | I15: PayPal | J15: 443.66 | K15: =IF(F15="",N15/(G15*(1-H15)),F15) -> 2 | L15: =IF(G15="",Table8[[#This Row],[Total_Amount2]]/(Table8[[#This Row],[Quantity]]*(1-Table8[[#This Row],[Discount]])),G15) -> 316.9 | M15: =IF(H15="",1-(Table8[[#This Row],[Total_Amount2]]/(Table8[[#This Row],[Quantity]]*Table8[[#This Row],[Unit_Price]])),H15) -> 0.3 | N15: =IF(J15="",F15*G15*(1-H15),J15) -> 443.66
A16: SALE14 | B16: 45829 | C16: CUST1348 | D16: PROD0 | E16: STORE15 | F16: 4 | G16: 403.47 | H16: 0.29 | I16: PayPal | J16: 1145.8548 | K16: =IF(F16="",N16/(G16*(1-H16)),F16) -> 4 | L16: =IF(G16="",Table8[[#This Row],[Total_Amount2]]/(Table8[[#This Row],[Quantity]]*(1-Table8[[#This Row],[Discount]])),G16) -> 403.47 | M16: =IF(H16="",1-(Table8[[#This Row],[Total_Amount2]]/(Table8[[#This Row],[Quantity]]*Table8[[#This Row],[Unit_Price]])),H16) -> 0.29 | N16: =IF(J16="",F16*G16*(1-H16),J16) -> 1145.8548
A17: SALE15 | B17: 45636 | C17: CUST1435 | D17: PROD0 | E17: STORE9 | G17: 871.34 | H17: 0.04 | I17: COD | J17: 2509.4592 | K17: =IF(F17="",N17/(G17*(1-H17)),F17) -> 3 | L17: =IF(G17="",Table8[[#This Row],[Total_Amount2]]/(Table8[[#This Row],[Quantity]]*(1-Table8[[#This Row],[Discount]])),G17) -> 871.34 | M17: =IF(H17="",1-(Table8[[#This Row],[Total_Amount2]]/(Table8[[#This Row],[Quantity]]*Table8[[#This Row],[Unit_Price]])),H17) -> 0.04 | N17: =IF(J17="",F17*G17*(1-H17),J17) -> 2509.4592
A18: SALE16 | B18: 45913 | C18: CUST1276 | D18: PROD1 | E18: STORE19 | F18: 2 | G18: 451.98 | H18: 0.25 | I18: Credit Card | J18: 677.97 | K18: =IF(F18="",N18/(G18*(1-H18)),F18) -> 2 | L18: =IF(G18="",Table8[[#This Row],[Total_Amount2]]/(Table8[[#This Row],[Quantity]]*(1-Table8[[#This Row],[Discount]])),G18) -> 451.98 | M18: =IF(H18="",1-(Table8[[#This Row],[Total_Amount2]]/(Table8[[#This Row],[Quantity]]*Table8[[#This Row],[Unit_Price]])),H18) -> 0.25 | N18: =IF(J18="",F18*G18*(1-H18),J18) -> 677.97
A19: SALE17 | B19: 45637 | C19: CUST1079 | D19: PROD1 | E19: STORE4 | F19: 2 | G19: 502.69 | H19: 0.23 | I19: Credit Card | J19: 774.1426 | K19: =IF(F19="",N19/(G19*(1-H19)),F19) -> 2 | L19: =IF(G19="",Table8[[#This Row],[Total_Amount2]]/(Table8[[#This Row],[Quantity]]*(1-Table8[[#This Row],[Discount]])),G19) -> 502.69 | M19: =IF(H19="",1-(Table8[[#This Row],[Total_Amount2]]/(Table8[[#This Row],[Quantity]]*Table8[[#This Row],[Unit_Price]])),H19) -> 0.23 | N19: =IF(J19="",F19*G19*(1-H19),J19) -> 774.1426
A20: SALE18 | B20: 45517 | C20: CUST1094 | D20: PROD1 | E20: STORE4 | F20: 2 | G20: 559.23 | H20: 0.25 | I20: COD | J20: 838.845 | K20: =IF(F20="",N20/(G20*(1-H20)),F20) -> 2 | L20: =IF(G20="",Table8[[#This Row],[Total_Amount2]]/(Table8[[#This Row],[Quantity]]*(1-Table8[[#This Row],[Discount]])),G20) -> 559.23 | M20: =IF(H20="",1-(Table8[[#This Row],[Total_Amount2]]/(Table8[[#This Row],[Quantity]]*Table8[[#This Row],[Unit_Price]])),H20) -> 0.25 | N20: =IF(J20="",F20*G20*(1-H20),J20) -> 838.845
A21: SALE19 | B21: 45369 | C21: CUST1239 | D21: PROD1 | E21: STORE13 | F21: 4 | H21: 0.04 | I21: COD | J21: 1782.4512 | K21: =IF(F21="",N21/(G21*(1-H21)),F21) -> 4 | L21: =IF(G21="",Table8[[#This Row],[Total_Amount2]]/(Table8[[#This Row],[Quantity]]*(1-Table8[[#This Row],[Discount]])),G21) -> 464.18 | M21: =IF(H21="",1-(Table8[[#This Row],[Total_Amount2]]/(Table8[[#This Row],[Quantity]]*Table8[[#This Row],[Unit_Price]])),H21) -> 0.04 | N21: =IF(J21="",F21*G21*(1-H21),J21) -> 1782.4512
A22: SALE20 | B22: 45843 | C22: CUST1144 | D22: PROD1 | E22: STORE17 | F22: 3 | G22: 986.04 | H22: 0.27 | I22: COD | J22: 2159.4276 | K22: =IF(F22="",N22/(G22*(1-H22)),F22) -> 3 | L22: =IF(G22="",Table8[[#This Row],[Total_Amount2]]/(Table8[[#This Row],[Quantity]]*(1-Table8[[#This Row],[Discount]])),G22) -> 986.04 | M22: =IF(H22="",1-(Table8[[#This Row],[Total_Amount2]]/(Table8[[#This Row],[Quantity]]*Table8[[#This Row],[Unit_Price]])),H22) -> 0.27 | N22: =IF(J22="",F22*G22*(1-H22),J22) -> 2159.4276
A23: SALE21 | B23: 45447 | C23: CUST1396 | D23: PROD1 | E23: STORE18 | F23: 1 | G23: 589.56 | H23: 0.22 | I23: Credit Card | J23: 459.8568 | K23: =IF(F23="",N23/(G23*(1-H23)),F23) -> 1 | L23: =IF(G23="",Table8[[#This Row],[Total_Amount2]]/(Table8[[#This Row],[Quantity]]*(1-Table8[[#This Row],[Discount]])),G23) -> 589.56 | M23: =IF(H23="",1-(Table8[[#This Row],[Total_Amount2]]/(Table8[[#This Row],[Quantity]]*Table8[[#This Row],[Unit_Price]])),H23) -> 0.22 | N23: =IF(J23="",F23*G23*(1-H23),J23) -> 459.8568
A24: SALE22 | B24: 45394 | C24: CUST1476 | D24: PROD1 | E24: STORE10 | F24: 3 | G24: 979.42 | H24: 0.03 | I24: PayPal | J24: 2850.1122 | K24: =IF(F24="",N24/(G24*(1-H24)),F24) -> 3 | L24: =IF(G24="",Table8[[#This Row],[Total_Amount2]]/(Table8[[#This Row],[Quantity]]*(1-Table8[[#This Row],[Discount]])),G24) -> 979.42 | M24: =IF(H24="",1-(Table8[[#This Row],[Total_Amount2]]/(Table8[[#This Row],[Quantity]]*Table8[[#This Row],[Unit_Price]])),H24) -> 0.03 | N24: =IF(J24="",F24*G24*(1-H24),J24) -> 2850.1122
A25: SALE23 | B25: 45466 | C25: CUST1368 | D25: PROD1 | E25: STORE8 | F25: 1 | G25: 719.28 | H25: 0.08 | I25: Credit Card | J25: 661.7376 | K25: =IF(F25="",N25/(G25*(1-H25)),F25) -> 1 | L25: =IF(G25="",Table8[[#This Row],[Total_Amount2]]/(Table8[[#This Row],[Quantity]]*(1-Table8[[#This Row],[Discount]])),G25) -> 719.28 | M25: =IF(H25="",1-(Table8[[#This Row],[Total_Amount2]]/(Table8[[#This Row],[Quantity]]*Table8[[#This Row],[Unit_Price]])),H25) -> 0.08 | N25: =IF(J25="",F25*G25*(1-H25),J25) -> 661.7376
A26: SALE24 | B26: 45908 | C26: CUST1186 | D26: PROD1 | E26: STORE6 | F26: 3 | G26: 77.6 | H26: 0.07 | I26: Credit Card | J26: 216.504 | K26: =IF(F26="",N26/(G26*(1-H26)),F26) -> 3 | L26: =IF(G26="",Table8[[#This Row],[Total_Amount2]]/(Table8[[#This Row],[Quantity]]*(1-Table8[[#This Row],[Discount]])),G26) -> 77.6 | M26: =IF(H26="",1-(Table8[[#This Row],[Total_Amount2]]/(Table8[[#This Row],[Quantity]]*Table8[[#This Row],[Unit_Price]])),H26) -> 0.07 | N26: =IF(J26="",F26*G26*(1-H26),J26) -> 216.504
A27: SALE25 | B27: 45552 | C27: CUST1381 | D27: PROD1 | E27: STORE3 | F27: 4 | G27: 852.71 | H27: 0.14 | I27: PayPal | J27: 2933.3224 | K27: =IF(F27="",N27/(G27*(1-H27)),F27) -> 4 | L27: =IF(G27="",Table8[[#This Row],[Total_Amount2]]/(Table8[[#This Row],[Quantity]]*(1-Table8[[#This Row],[Discount]])),G27) -> 852.71 | M27: =IF(H27="",1-(Table8[[#This Row],[Total_Amount2]]/(Table8[[#This Row],[Quantity]]*Table8[[#This Row],[Unit_Price]])),H27) -> 0.14 | N27: =IF(J27="",F27*G27*(1-H27),J27) -> 2933.3224
A28: SALE26 | B28: 45294 | C28: CUST1213 | D28: PROD1 | E28: STORE8 | F28: 4 | G28: 156.16 | I28: Credit Card | J28: 599.6544 | K28: =IF(F28="",N28/(G28*(1-H28)),F28) -> 4 | L28: =IF(G28="",Table8[[#This Row],[Total_Amount2]]/(Table8[[#This Row],[Quantity]]*(1-Table8[[#This Row],[Discount]])),G28) -> 156.16 | M28: =IF(H28="",1-(Table8[[#This Row],[Total_Amount2]]/(Table8[[#This Row],[Quantity]]*Table8[[#This Row],[Unit_Price]])),H28) -> 0.04 | N28: =IF(J28="",F28*G28*(1-H28),J28) -> 599.6544
A29: SALE27 | B29: 45710 | C29: CUST1200 | D29: PROD1 | E29: STORE8 | F29: 3 | G29: 815.49 | H29: 0.17 | I29: Credit Card | J29: 2030.5701 | K29: =IF(F29="",N29/(G29*(1-H29)),F29) -> 3 | L29: =IF(G29="",Table8[[#This Row],[Total_Amount2]]/(Table8[[#This Row],[Quantity]]*(1-Table8[[#This Row],[Discount]])),G29) -> 815.49 | M29: =IF(H29="",1-(Table8[[#This Row],[Total_Amount2]]/(Table8[[#This Row],[Quantity]]*Table8[[#This Row],[Unit_Price]])),H29) -> 0.17 | N29: =IF(J29="",F29*G29*(1-H29),J29) -> 2030.5701
A30: SALE28 | B30: 45923 | C30: CUST1148 | D30: PROD1 | E30: STORE2 | F30: 2 | G30: 74.21 | H30: 0.11 | I30: PayPal | J30: 132.0938 | K30: =IF(F30="",N30/(G30*(1-H30)),F30) -> 2 | L30: =IF(G30="",Table8[[#This Row],[Total_Amount2]]/(Table8[[#This Row],[Quantity]]*(1-Table8[[#This Row],[Discount]])),G30) -> 74.21 | M30: =IF(H30="",1-(Table8[[#This Row],[Total_Amount2]]/(Table8[[#This Row],[Quantity]]*Table8[[#This Row],[Unit_Price]])),H30) -> 0.11 | N30: =IF(J30="",F30*G30*(1-H30),J30) -> 132.0938
A31: SALE29 | B31: 45302 | C31: CUST1348 | D31: PROD1 | E31: STORE3 | G31: 451.67 | H31: 0.15 | I31: Credit Card | J31: 1535.678 | K31: =IF(F31="",N31/(G31*(1-H31)),F31) -> 4 | L31: =IF(G31="",Table8[[#This Row],[Total_Amount2]]/(Table8[[#This Row],[Quantity]]*(1-Table8[[#This Row],[Discount]])),G31) -> 451.67 | M31: =IF(H31="",1-(Table8[[#This Row],[Total_Amount2]]/(Table8[[#This Row],[Quantity]]*Table8[[#This Row],[Unit_Price]])),H31) -> 0.15 | N31: =IF(J31="",F31*G31*(1-H31),J31) -> 1535.678
A32: SALE30 | B32: 45217 | C32: CUST1028 | D32: PROD1 | E32: STORE19 | F32: 1 | G32: 429.38 | H32: 0.13 | I32: PayPal | J32: 373.5606 | K32: =IF(F32="",N32/(G32*(1-H32)),F32) -> 1 | L32: =IF(G32="",Table8[[#This Row],[Total_Amount2]]/(Table8[[#This Row],[Quantity]]*(1-Table8[[#This Row],[Discount]])),G32) -> 429.38 | M32: =IF(H32="",1-(Table8[[#This Row],[Total_Amount2]]/(Table8[[#This Row],[Quantity]]*Table8[[#This Row],[Unit_Price]])),H32) -> 0.13 | N32: =IF(J32="",F32*G32*(1-H32),J32) -> 373.5606
A33: SALE31 | B33: 45593 | C33: CUST1412 | D33: PROD10 | E33: STORE12 | F33: 2 | G33: 148.96 | H33: 0.03 | I33: COD | J33: 288.9824 | K33: =IF(F33="",N33/(G33*(1-H33)),F33) -> 2 | L33: =IF(G33="",Table8[[#This Row],[Total_Amount2]]/(Table8[[#This Row],[Quantity]]*(1-Table8[[#This Row],[Discount]])),G33) -> 148.96 | M33: =IF(H33="",1-(Table8[[#This Row],[Total_Amount2]]/(Table8[[#This Row],[Quantity]]*Table8[[#This Row],[Unit_Price]])),H33) -> 0.03 | N33: =IF(J33="",F33*G33*(1-H33),J33) -> 288.9824
A34: SALE32 | B34: 45597 | C34: CUST1398 | D34: PROD10 | E34: STORE8 | F34: 4 | G34: 313.83 | H34: 0.08 | I34: Credit Card | J34: 1154.8944 | K34: =IF(F34="",N34/(G34*(1-H34)),F34) -> 4 | L34: =IF(G34="",Table8[[#This Row],[Total_Amount2]]/(Table8[[#This Row],[Quantity]]*(1-Table8[[#This Row],[Discount]])),G34) -> 313.83 | M34: =IF(H34="",1-(Table8[[#This Row],[Total_Amount2]]/(Table8[[#This Row],[Quantity]]*Table8[[#This Row],[Unit_Price]])),H34) -> 0.08 | N34: =IF(J34="",F34*G34*(1-H34),J34) -> 1154.8944
A35: SALE33 | B35: 45620 | C35: CUST1453 | D35: PROD10 | E35: STORE6 | F35: 2 | G35: 717.31 | H35: 0.15 | I35: Credit Card | J35: 1219.427 | K35: =IF(F35="",N35/(G35*(1-H35)),F35) -> 2 | L35: =IF(G35="",Table8[[#This Row],[Total_Amount2]]/(Table8[[#This Row],[Quantity]]*(1-Table8[[#This Row],[Discount]])),G35) -> 717.31 | M35: =IF(H35="",1-(Table8[[#This Row],[Total_Amount2]]/(Table8[[#This Row],[Quantity]]*Table8[[#This Row],[Unit_Price]])),H35) -> 0.15 | N35: =IF(J35="",F35*G35*(1-H35),J35) -> 1219.427
A36: SALE34 | B36: 45215 | C36: CUST1344 | D36: PROD10 | E36: STORE1 | G36: 873.22 | H36: 0.18 | I36: Credit Card | J36: 2148.1212 | K36: =IF(F36="",N36/(G36*(1-H36)),F36) -> 3 | L36: =IF(G36="",Table8[[#This Row],[Total_Amount2]]/(Table8[[#This Row],[Quantity]]*(1-Table8[[#This Row],[Discount]])),G36) -> 873.22 | M36: =IF(H36="",1-(Table8[[#This Row],[Total_Amount2]]/(Table8[[#This Row],[Quantity]]*Table8[[#This Row],[Unit_Price]])),H36) -> 0.18 | N36: =IF(J36="",F36*G36*(1-H36),J36) -> 2148.1212
A37: SALE35 | B37: 45878 | C37: CUST1218 | D37: PROD10 | E37: STORE3 | F37: 4 | G37: 109.36 | H37: 0.19 | I37: COD | J37: 354.3264 | K37: =IF(F37="",N37/(G37*(1-H37)),F37) -> 4 | L37: =IF(G37="",Table8[[#This Row],[Total_Amount2]]/(Table8[[#This Row],[Quantity]]*(1-Table8[[#This Row],[Discount]])),G37) -> 109.36 | M37: =IF(H37="",1-(Table8[[#This Row],[Total_Amount2]]/(Table8[[#This Row],[Quantity]]*Table8[[#This Row],[Unit_Price]])),H37) -> 0.19 | N37: =IF(J37="",F37*G37*(1-H37),J37) -> 354.3264
A38: SALE36 | B38: 45635 | C38: CUST1086 | D38: PROD10 | E38: STORE7 | F38: 3 | G38: 559.52 | H38: 0.16 | I38: PayPal | J38: 1409.9904 | K38: =IF(F38="",N38/(G38*(1-H38)),F38) -> 3 | L38: =IF(G38="",Table8[[#This Row],[Total_Amount2]]/(Table8[[#This Row],[Quantity]]*(1-Table8[[#This Row],[Discount]])),G38) -> 559.52 | M38: =IF(H38="",1-(Table8[[#This Row],[Total_Amount2]]/(Table8[[#This Row],[Quantity]]*Table8[[#This Row],[Unit_Price]])),H38) -> 0.16 | N38: =IF(J38="",F38*G38*(1-H38),J38) -> 1409.9904
A39: SALE37 | B39: 45329 | C39: CUST1492 | D39: PROD10 | E39: STORE17 | F39: 3 | G39: 121.76 | H39: 0.27 | I39: PayPal | J39: 266.6544 | K39: =IF(F39="",N39/(G39*(1-H39)),F39) -> 3 | L39: =IF(G39="",Table8[[#This Row],[Total_Amount2]]/(Table8[[#This Row],[Quantity]]*(1-Table8[[#This Row],[Discount]])),G39) -> 121.76 | M39: =IF(H39="",1-(Table8[[#This Row],[Total_Amount2]]/(Table8[[#This Row],[Quantity]]*Table8[[#This Row],[Unit_Price]])),H39) -> 0.27 | N39: =IF(J39="",F39*G39*(1-H39),J39) -> 266.6544
A40: SALE38 | B40: 45378 | C40: CUST1189 | D40: PROD10 | E40: STORE13 | F40: 4 | G40: 735.32 | H40: 0.06 | I40: COD | J40: 2764.8032 | K40: =IF(F40="",N40/(G40*(1-H40)),F40) -> 4 | L40: =IF(G40="",Table8[[#This Row],[Total_Amount2]]/(Table8[[#This Row],[Quantity]]*(1-Table8[[#This Row],[Discount]])),G40) -> 735.32 | M40: =IF(H40="",1-(Table8[[#This Row],[Total_Amount2]]/(Table8[[#This Row],[Quantity]]*Table8[[#This Row],[Unit_Price]])),H40) -> 0.06 | N40: =IF(J40="",F40*G40*(1-H40),J40) -> 2764.8032
...

Sheet Customer_Dim Cleaned
A1: Customer_ID | B1: Name | C1: Age | D1: Gender | E1: City | F1: State | G1: Country | H1: Loyalty_Level | J1: Cleaning Process
A2: CUST1000 | B2: Sheena Bonilla | C2: 55 | D2: Male | E2: Donaldton | F2: North Carolina | G2: USA | H2: Platinum | J2: 1.There are some inconsistencies found in Customer_ID and Name column that are corrected.
A3: CUST1001 | B3: Eugene Nelson | C3: 26 | D3: Female | E3: Phillipsmouth | F3: North Dakota | G3: USA | H3: Platinum | J3: 2.Missing values in Loyality_Level column has imputed by Mode function.
A4: CUST1002 | B4: Dr. Benjamin Price | C4: 29 | D4: Female | E4: Kylebury | F4: Alabama | G4: USA | H4: Platinum
A5: CUST1003 | B5: Jeremy Harris | C5: 59 | D5: Female | E5: Thomastown | F5: Ohio | G5: USA | H5: Bronze
A6: CUST1004 | B6: Caroline Collins | C6: 64 | D6: Female | E6: Nicholasshire | F6: California | G6: USA | H6: Silver
A7: CUST1005 | B7: Christine Vaughn | C7: 24 | D7: Male | E7: East Amandamouth | F7: Oregon | G7: USA | H7: Bronze
A8: CUST1006 | B8: Amber Jackson | C8: 29 | D8: Female | E8: Deborahborough | F8: South Dakota | G8: USA | H8: Platinum
A9: CUST1007 | B9: Daniel Boyd | C9: 29 | D9: Female | E9: West Pamelafurt | F9: West Virginia | G9: USA | H9: Bronze
A10: CUST1008 | B10: Melissa Howard | C10: 53 | D10: Female | E10: Maynardton | F10: New Hampshire | G10: USA | H10: Gold
A11: CUST1009 | B11: Ms. Maria Leach | C11: 64 | D11: Male | E11: Melissashire | F11: Pennsylvania | G11: USA | H11: Platinum
A12: CUST1010 | B12: Dominic Page | C12: 53 | D12: Male | E12: Port Michaelburgh | F12: Pennsylvania | G12: USA | H12: Bronze
A13: CUST1011 | B13: Brian Lopez | C13: 28 | D13: Female | E13: East Krista | F13: New York | G13: USA | H13: Gold
A14: CUST1012 | B14: Kenneth Lambert | C14: 55 | D14: Female | E14: North Kathryn | F14: Kansas | G14: USA | H14: Platinum
A15: CUST1013 | B15: Nathan Hernandez | C15: 32 | D15: Female | E15: New Becky | F15: Montana | G15: USA | H15: Silver
... A501: CUST1499 | B501: Philip Pennington | C501: 27 | D501: Female | E501: East Valerieview | F501: Oregon | G501: USA | H501: Platinum

Sheet Product_Dim Cleaned
A1: Product_ID | B1: Product_Name | C1: Category | D1: Sub_Category | E1: Brand | F1: Cost | G1: Stock | J1: Cleaning Process
A2: PROD0 | B2: Brother Laser Printer | C2: Electronics | D2: Computer | E2: Hunt Inc | F2: 112.42 | G2: 416 | J2: 1.Inconsistency found in Product_ID column and that are corrected.
A3: PROD1 | B3: Men's Graphic T-Shirt | C3: Clothing | D3: Tops | E3: Terry-Moore | F3: 342.56 | G3: 181 | J3: 2.Some values are Missing in Cost and Stock column that are imputed by
A4: PROD2 | B4: Women's Casual Hoodie | C4: Clothing | D4: Outerwear | E4: Sims Inc | F4: 296.82667 | G4: 352 | J4: COST=IF(F2="",AVERAGEIFS($F$2:$F$101,$C$2:$C$101,C2,$D$2:$D$101,D2),F2)
A5: PROD3 | B5: Men's Running Jacket | C5: Clothing | D5: Outerwear | E5: Pineda Ltd | F5: 364.67 | G5: 452
A6: PROD4 | B6: Women's Yoga Pants | C6: Clothing | D6: Bottoms | E6: Gonzales-Davis | F6: 306.46 | G6: 487 | J6: STOCK=IF(G2="",MEDIAN(IF(($C$2:$C$101=C2)*($D$2:$D$101=D2),$G$2:$G$101)),G2)
A7: PROD5 | B7: Men's Leather Belt | C7: Clothing | D7: Accessories | E7: Baldwin, Garza and Gonzalez | F7: 261 | G7: 59
A8: PROD6 | B8: Herbal Face Moisturizer | C8: Beauty | D8: Skincare | E8: Davidson PLC | F8: 312.8 | G8: 350
A9: PROD7 | B9: LED Table Lamp | C9: Home | D9: Lighting | E9: Harrell LLC | F9: 218.86 | G9: 170
A10: PROD8 | B10: Wireless Bluetooth Earbuds | C10: Electronics | D10: Audio | E10: Perez-Johnston | F10: 439.07 | G10: 142
A11: PROD9 | B11: Adjustable Dumbbell Set | C11: Sports | D11: Fitness | E11: Hill PLC | F11: 495.72 | G11: 323
A12: PROD10 | B12: Ceramic Kitchen Bowl Set | C12: Home | D12: Kitchen | E12: Hamilton Group | F12: 298.86 | G12: 308
A13: PROD11 | B13: HD Smart TV Stick | C13: Electronics | D13: Accessories | E13: Gibson, Hobbs and Weaver | F13: 449.4 | G13: 361
A14: PROD12 | B14: Hair Strengthening Shampoo | C14: Beauty | D14: Haircare | E14: Rice LLC | F14: 115.82 | G14: 460
A15: PROD13 | B15: USB-C Fast Charger | C15: Electronics | D15: Accessories | E15: Dawson-Perkins | F15: 242.23 | G15: 453
A16: PROD14 | B16: Decorative Wall Mirror | C16: Home | D16: Decor | E16: Luna, Anderson and Bowman | F16: 48.01 | G16: 439
A17: PROD15 | B17: 4K Home Projector | C17: Electronics | D17: Appliances | E17: Thomas LLC | F17: 465.34 | G17: 301
A18: PROD16 | B18: Beard Grooming Kit | C18: Beauty | D18: Grooming | E18: Erickson-Green | F18: 337.42 | G18: 256
... A101: PROD99 | B101: Stainless Steel Cookware Set | C101: Home | D101: Kitchen | E101: Campbell Ltd | F101: 201.41 | G101: 146

Sheet Store_Dim
A1: Store_ID | B1: Store_Name | C1: Region | D1: City | E1: Store_Type | G1: Cleaning Process
A2: STORE0 | B2: Rivera-Warner | C2: East | D2: Washingtonfurt | E2: Flagship | G2: 1.There is no inconsistency found.
A3: STORE1 | B3: Martinez, Adkins and Johnson | C3: North | D3: Danielmouth | E3: Flagship | G3: 2.Tables created and text formatting done
A4: STORE2 | B4: Black-Horn | C4: South | D4: North Nancyview | E4: Outlet
A5: STORE3 | B5: Johnson-Wright | C5: North | D5: Hoodberg | E5: Outlet
A6: STORE4 | B6: Alexander Group | C6: South | D6: Port Sharon | E6: Online
A7: STORE5 | B7: Gray Ltd | C7: North | D7: New Michaelchester | E7: Outlet
A8: STORE6 | B8: Benson-Elliott | C8: East | D8: Port Josephberg | E8: Online
A9: STORE7 | B9: Martinez-Mullins | C9: South | D9: Williamsfurt | E9: Online
A10: STORE8 | B10: Bean, Jones and Park | C10: West | D10: Thompsonborough | E10: Online
A11: STORE9 | B11: Moore, Padilla and Butler | C11: South | D11: East Johnstad | E11: Flagship
A12: STORE10 | B12: Hill, Wagner and Ballard | C12: East | D12: East Davidville | E12: Online
A13: STORE11 | B13: Aguirre-Keller | C13: South | D13: Lake Michael | E13: Online
A14: STORE12 | B14: Thomas, Bridges and Harris | C14: North | D14: Sabrinatown | E14: Online
A15: STORE13 | B15: Gardner, Humphrey and Contreras | C15: East | D15: Johnsonville | E15: Flagship
... A21: STORE19 | B21: Mann-Austin | C21: East | D21: Vasquezborough | E21: Online

Sheet Sales_Fact Cleaned
A1: Sales_ID | B1: Order_Date | C1: Customer_ID | D1: Gender | E1: City | F1: State | G1: Product_ID | H1: Product_Name | I1: Category | J1: Sub_Category | K1: Store_ID | L1: Quantity | M1: Unit_Price | N1: Discount | O1: Payment_Type | P1: Total_Amount | S1: Cleaning Process
A2: SALE0 | B2: 45480 | C2: CUST1409 | D2: =VLOOKUP($C2,'Customer_Dim Cleaned'!$A$1:$H$501,4,FALSE) -> Male | E2: =VLOOKUP($C2,'Customer_Dim Cleaned'!$A$1:$H$501,5,FALSE) -> Kathleenport | F2: =VLOOKUP($C2,'Customer_Dim Cleaned'!$A$1:$H$501,6,FALSE) -> Wyoming | G2: PROD0 | H2: =VLOOKUP($G2,'Product_Dim Cleaned'!$A$1:$G$101,2,FALSE) -> Brother Laser Printer | I2: =VLOOKUP($G2,'Product_Dim Cleaned'!$A$1:$G$101,3,FALSE) -> Electronics | J2: =VLOOKUP($G2,'Product_Dim Cleaned'!$A$1:$G$101,4,FALSE) -> Computer | K2: STORE3 | L2: 1 | M2: 218.04 | N2: 0.09 | O2: Credit Card | P2: 198.4164 | R2: 1 | S2: Order_Date column datatype changed.
A3: SALE1 | B3: 45285 | C3: CUST1467 | D3: =VLOOKUP($C3,'Customer_Dim Cleaned'!$A$1:$H$501,4,FALSE) -> Female | E3: =VLOOKUP($C3,'Customer_Dim Cleaned'!$A$1:$H$501,5,FALSE) -> Oneillfurt | F3: =VLOOKUP($C3,'Customer_Dim Cleaned'!$A$1:$H$501,6,FALSE) -> Vermont | G3: PROD0 | H3: =VLOOKUP($G3,'Product_Dim Cleaned'!$A$1:$G$101,2,FALSE) -> Brother Laser Printer | I3: =VLOOKUP($G3,'Product_Dim Cleaned'!$A$1:$G$101,3,FALSE) -> Electronics | J3: =VLOOKUP($G3,'Product_Dim Cleaned'!$A$1:$G$101,4,FALSE) -> Computer | K3: STORE17 | L3: 3 | M3: 104.47 | N3: 0.27 | O3: PayPal | P3: 228.7893 | R3: 2 | S3: Numerical column missing values are imputed by
A4: SALE2 | B4: 45446 | C4: CUST1056 | D4: =VLOOKUP($C4,'Customer_Dim Cleaned'!$A$1:$H$501,4,FALSE) -> Female | E4: =VLOOKUP($C4,'Customer_Dim Cleaned'!$A$1:$H$501,5,FALSE) -> Deborahberg | F4: =VLOOKUP($C4,'Customer_Dim Cleaned'!$A$1:$H$501,6,FALSE) -> Pennsylvania | G4: PROD0 | H4: =VLOOKUP($G4,'Product_Dim Cleaned'!$A$1:$G$101,2,FALSE) -> Brother Laser Printer | I4: =VLOOKUP($G4,'Product_Dim Cleaned'!$A$1:$G$101,3,FALSE) -> Electronics | J4: =VLOOKUP($G4,'Product_Dim Cleaned'!$A$1:$G$101,4,FALSE) -> Computer | K4: STORE8 | L4: 4 | M4: 914.05 | N4: 0.25 | O4: Credit Card | P4: 2742.15
A5: SALE3 | B5: 45259 | C5: CUST1346 | D5: =VLOOKUP($C5,'Customer_Dim Cleaned'!$A$1:$H$501,4,FALSE) -> Female | E5: =VLOOKUP($C5,'Customer_Dim Cleaned'!$A$1:$H$501,5,FALSE) -> Port Crystalberg | F5: =VLOOKUP($C5,'Customer_Dim Cleaned'!$A$1:$H$501,6,FALSE) -> Tennessee | G5: PROD0 | H5: =VLOOKUP($G5,'Product_Dim Cleaned'!$A$1:$G$101,2,FALSE) -> Brother Laser Printer | I5: =VLOOKUP($G5,'Product_Dim Cleaned'!$A$1:$G$101,3,FALSE) -> Electronics | J5: =VLOOKUP($G5,'Product_Dim Cleaned'!$A$1:$G$101,4,FALSE) -> Computer | K5: STORE8 | L5: 1 | M5: 921.51 | N5: 0.16 | O5: COD | P5: 774.0684 | S5: Quantity=IF(F2="",N2/(G2*(1-H2)),F2)
A6: SALE4 | B6: 45297 | C6: CUST1493 | D6: =VLOOKUP($C6,'Customer_Dim Cleaned'!$A$1:$H$501,4,FALSE) -> Male | E6: =VLOOKUP($C6,'Customer_Dim Cleaned'!$A$1:$H$501,5,FALSE) -> South William | F6: =VLOOKUP($C6,'Customer_Dim Cleaned'!$A$1:$H$501,6,FALSE) -> Alabama | G6: PROD0 | H6: =VLOOKUP($G6,'Product_Dim Cleaned'!$A$1:$G$101,2,FALSE) -> Brother Laser Printer | I6: =VLOOKUP($G6,'Product_Dim Cleaned'!$A$1:$G$101,3,FALSE) -> Electronics | J6: =VLOOKUP($G6,'Product_Dim Cleaned'!$A$1:$G$101,4,FALSE) -> Computer | K6: STORE5 | L6: 3 | M6: 745.3 | N6: 0.18 | O6: Credit Card | P6: 1833.438 | S6: Unit_Price=IF(G2="",[@[Total_Amount2]]/([@Quantity]*(1-[@Discount])),G2)
A7: SALE5 | B7: 45499 | C7: CUST1116 | D7: =VLOOKUP($C7,'Customer_Dim Cleaned'!$A$1:$H$501,4,FALSE) -> Female | E7: =VLOOKUP($C7,'Customer_Dim Cleaned'!$A$1:$H$501,5,FALSE) -> North Davidport | F7: =VLOOKUP($C7,'Customer_Dim Cleaned'!$A$1:$H$501,6,FALSE) -> Rhode Island | G7: PROD0 | H7: =VLOOKUP($G7,'Product_Dim Cleaned'!$A$1:$G$101,2,FALSE) -> Brother Laser Printer | I7: =VLOOKUP($G7,'Product_Dim Cleaned'!$A$1:$G$101,3,FALSE) -> Electronics | J7: =VLOOKUP($G7,'Product_Dim Cleaned'!$A$1:$G$101,4,FALSE) -> Computer | K7: STORE7 | L7: 3 | M7: 147.01 | N7: 0.19 | O7: COD | P7: 357.2343 | S7: Discount=IF(H2="",1-([@[Total_Amount2]]/([@Quantity]*[@[Unit_Price]])),H2)
A8: SALE6 | B8: 45850 | C8: CUST1016 | D8: =VLOOKUP($C8,'Customer_Dim Cleaned'!$A$1:$H$501,4,FALSE) -> Female | E8: =VLOOKUP($C8,'Customer_Dim Cleaned'!$A$1:$H$501,5,FALSE) -> South Christopher | F8: =VLOOKUP($C8,'Customer_Dim Cleaned'!$A$1:$H$501,6,FALSE) -> Pennsylvania | G8: PROD0 | H8: =VLOOKUP($G8,'Product_Dim Cleaned'!$A$1:$G$101,2,FALSE) -> Brother Laser Printer | I8: =VLOOKUP($G8,'Product_Dim Cleaned'!$A$1:$G$101,3,FALSE) -> Electronics | J8: =VLOOKUP($G8,'Product_Dim Cleaned'!$A$1:$G$101,4,FALSE) -> Computer | K8: STORE4 | L8: 2 | M8: 785.31 | N8: 0.15 | O8: PayPal | P8: 1335.027 | S8: Total_Amount=IF(J2="",F2*G2*(1-H2),J2)
A9: SALE7 | B9: 45248 | C9: CUST1152 | D9: =VLOOKUP($C9,'Customer_Dim Cleaned'!$A$1:$H$501,4,FALSE) -> Female | E9: =VLOOKUP($C9,'Customer_Dim Cleaned'!$A$1:$H$501,5,FALSE) -> Jaredville | F9: =VLOOKUP($C9,'Customer_Dim Cleaned'!$A$1:$H$501,6,FALSE) -> Missouri | G9: PROD0 | H9: =VLOOKUP($G9,'Product_Dim Cleaned'!$A$1:$G$101,2,FALSE) -> Brother Laser Printer | I9: =VLOOKUP($G9,'Product_Dim Cleaned'!$A$1:$G$101,3,FALSE) -> Electronics | J9: =VLOOKUP($G9,'Product_Dim Cleaned'!$A$1:$G$101,4,FALSE) -> Computer | K9: STORE8 | L9: 4 | M9: 342.39 | N9: 0.23 | O9: PayPal | P9: 1054.5612
A10: SALE8 | B10: 45781 | C10: CUST1187 | D10: =VLOOKUP($C10,'Customer_Dim Cleaned'!$A$1:$H$501,4,FALSE) -> Female | E10: =VLOOKUP($C10,'Customer_Dim Cleaned'!$A$1:$H$501,5,FALSE) -> Lake Blaketon | F10: =VLOOKUP($C10,'Customer_Dim Cleaned'!$A$1:$H$501,6,FALSE) -> Alabama | G10: PROD0 | H10: =VLOOKUP($G10,'Product_Dim Cleaned'!$A$1:$G$101,2,FALSE) -> Brother Laser Printer | I10: =VLOOKUP($G10,'Product_Dim Cleaned'!$A$1:$G$101,3,FALSE) -> Electronics | J10: =VLOOKUP($G10,'Product_Dim Cleaned'!$A$1:$G$101,4,FALSE) -> Computer | K10: STORE5 | L10: 3 | M10: 448.25 | N10: 0.07 | O10: PayPal | P10: 1250.6175 | R10: 3 | S10: Conditional formatting applied as follows
A11: SALE9 | B11: 45869 | C11: CUST1464 | D11: =VLOOKUP($C11,'Customer_Dim Cleaned'!$A$1:$H$501,4,FALSE) -> Female | E11: =VLOOKUP($C11,'Customer_Dim Cleaned'!$A$1:$H$501,5,FALSE) -> Grayland | F11: =VLOOKUP($C11,'Customer_Dim Cleaned'!$A$1:$H$501,6,FALSE) -> Washington | G11: PROD0 | H11: =VLOOKUP($G11,'Product_Dim Cleaned'!$A$1:$G$101,2,FALSE) -> Brother Laser Printer | I11: =VLOOKUP($G11,'Product_Dim Cleaned'!$A$1:$G$101,3,FALSE) -> Electronics | J11: =VLOOKUP($G11,'Product_Dim Cleaned'!$A$1:$G$101,4,FALSE) -> Computer | K11: STORE0 | L11: 2 | M11: 873.17 | N11: 0.23 | O11: PayPal | P11: 1344.6818 | S11: color scales applied on Unit_Price
A12: SALE10 | B12: 45335 | C12: CUST1065 | D12: =VLOOKUP($C12,'Customer_Dim Cleaned'!$A$1:$H$501,4,FALSE) -> Female | E12: =VLOOKUP($C12,'Customer_Dim Cleaned'!$A$1:$H$501,5,FALSE) -> Woodmouth | F12: =VLOOKUP($C12,'Customer_Dim Cleaned'!$A$1:$H$501,6,FALSE) -> Nevada | G12: PROD0 | H12: =VLOOKUP($G12,'Product_Dim Cleaned'!$A$1:$G$101,2,FALSE) -> Brother Laser Printer | I12: =VLOOKUP($G12,'Product_Dim Cleaned'!$A$1:$G$101,3,FALSE) -> Electronics | J12: =VLOOKUP($G12,'Product_Dim Cleaned'!$A$1:$G$101,4,FALSE) -> Computer | K12: STORE14 | L12: 1 | M12: 278.63 | N12: 0.07 | O12: Credit Card | P12: 259.1259 | S12: Top 10 discount % highlighted in Discount column
